[2017-06-05 01:04:42,728] ERROR in app: Exception on /query/我想要大便 [GET]
Traceback (most recent call last):
  File "/home/andy/anaconda2/lib/python2.7/site-packages/flask/app.py", line 1988, in wsgi_app
    response = self.full_dispatch_request()
  File "/home/andy/anaconda2/lib/python2.7/site-packages/flask/app.py", line 1641, in full_dispatch_request
    rv = self.handle_user_exception(e)
  File "/home/andy/anaconda2/lib/python2.7/site-packages/flask/app.py", line 1544, in handle_user_exception
    reraise(exc_type, exc_value, tb)
  File "/home/andy/anaconda2/lib/python2.7/site-packages/flask/app.py", line 1639, in full_dispatch_request
    rv = self.dispatch_request()
  File "/home/andy/anaconda2/lib/python2.7/site-packages/flask/app.py", line 1625, in dispatch_request
    return self.view_functions[rule.endpoint](**req.view_args)
  File "runserver.py", line 30, in query
    res = pttbot.process(sentence)
  File "/home/andy/PTTBot/agent_server.py", line 176, in process
    print('[action] ->>' + str(action))
UnboundLocalError: local variable 'action' referenced before assignment
Error in atexit._run_exitfuncs:
Traceback (most recent call last):
  File "/home/andy/anaconda2/lib/python2.7/atexit.py", line 24, in _run_exitfuncs
    func(*targs, **kargs)
  File "/home/andy/anaconda2/lib/python2.7/site-packages/theano/gof/cmodule.py", line 1492, in _on_atexit
    self.clear_old()
  File "/home/andy/anaconda2/lib/python2.7/site-packages/theano/gof/cmodule.py", line 1295, in clear_old
    cleanup=False)
  File "/home/andy/anaconda2/lib/python2.7/site-packages/theano/gof/cmodule.py", line 943, in refresh
    open(entry).close()
KeyboardInterrupt
